Workbook

Sheet 목록
B2: 작 성 양 식
E8: 1. 기초 재무상태 조사
E10: 2. 중장기 영농목표
E12: 3. 투자계획
E14: 4. 원리금상환계획
E16: 5. 판매계획
E18: 6. 생산계획
E20: 7. 영농자재소요계획
E22: 8. 노무비계획
E24: 9. 경비계획
E26: 10. 감가상각비계획
E28: 11. 생산원가계획
E30: 12. 손익계획
... E36: 15. 추정소득분석

Sheet 1. 기초재무상태조사
B2: 1. 기초 재무상태 조사
B4: 가. 자산
B6: (1) 토지
B8: 종류 | C8: 주소(지번) | D8: 면적(㎡) | E8: 평가액(천원) | F8: 구입년도 | H8: 비고
B12: (2) 건물및구축물
B14: 종류 | C14: 구조 | D14: 규모(㎡) | E14: 평가액(천원) | F14: 내용연수 | G14: 설치년도 | H14: 비고
B18: (3) 대식물
B20: 품목 | C20: 품종 | D20: 주수 | E20: 평가액(천원) | F20: 경제수령 | G20: 식재년도 | H20: 비고
B24: (4) 대동물
B26: 축종 | C26: 품종 | D26: 암수 | E26: 축령(월령) | F26: 두수 | G26: 단가(천원) | H26: 금액(천원)
B30: (5) 대농기계 및 차량운반구 등
B32: 종류 | C32: 규격 | D32: 대수 | E32: 구입가격(천원) | F32: 내용연수 | G32: 구입년도 | H32: 비고
B36: (6) 현금 및 준현금
B38: 종류 | C38: 명칭 | E38: 평가액(천원) | G38: 비고
B39: 현금 | C39: 예금
B41: 합계 | E41: =SUM(E39:F39)
B43: (7) 재고생산자재
B45: 종류 | C45: 품명/규격 | D45: 수량 | E45: 단가(천원) | F45: 금액(천원) | G45: 비고
B49: (8) 재고농산물
B51: 종류 | C51: 품종 등 | D51: 수량 | E51: 단가(천원) | F51: 평가액(천원) | G51: 생산년도 | H51: 비고
B55: 나. 부채
B57: 종류 | C57: 용도 | D57: 자금종류 | E57: 융자금액(천원) | F57: 융자년도 | G57: 원리금 상환조건

Sheet 2. 중장기영농목표
B2: 2. 중장기 영농목표
B4: 가. 작성기간 : 5개년 계획
B7: 나. 매출액 및 순이익 목표
H8: (단위:천원)
B9: 구 분 | H9: 비고
B10: 매출액 | C10: ='12 손익계획'!C6 | D10: ='12 손익계획'!D6 | E10: ='12 손익계획'!E6 | F10: ='12 손익계획'!F6 | G10: ='12 손익계획'!G6
B11: 순이익 | C11: ='12 손익계획'!C26 | D11: ='12 손익계획'!D26 | E11: ='12 손익계획'!E26 | F11: ='12 손익계획'!F26 | G11: ='12 손익계획'!G26
B12: 순이익률(%) | C12: =C11/C10 | D12: =D11/D10 | E12: =E11/E10 | F12: =F11/F10 | G12: =G11/G10

Sheet 3.투자계획
B2: 3. 투자계획
B4: 가. 총괄 투자계획
I5: (단위:천원)
B6: 투자연도 | C6: 소요액 | D6: 투자재원 | G6: 비고
D7: 자부담 | E7: 보조 | F7: 융자
C8: =SUM(D8:F8) | D8: =F24 | F8: =H24
B9: =B8+1 | C9: =SUM(D9:F9) | D9: =F25 | E9: =G25 | F9: =H25
B10: =B9+1 | C10: =SUM(D10:F10) | D10: =F26 | E10: =G26 | F10: =H26
B11: =B10+1 | C11: =SUM(D11:F11) | D11: =F27 | E11: =G27 | F11: =H27
B12: =B11+1 | C12: =SUM(D12:F12) | D12: =F28 | E12: =G28 | F12: =H28
B13: 합 계 | C13: =SUM(C8:C12) | D13: =SUM(D8:D12) | E13: =SUM(E8:E12) | F13: =SUM(F8:F12)
B15: 나. 연차별 세부투자계획
I16: (단위:천원)
B17: 연도별 | C17: 투자대상 | E17: 투자금액(천원) | I17: 비 고
C18: 투자항목 | D18: 규격 | E18: 계 | F18: 자부담 | G18: 보조 | H18: 융자
B19: =B8 | E19: =SUM(F19:H19)
E20: =SUM(F20:H20)
E21: =SUM(F21:H21)
E22: =SUM(F22:H22) | F22: =0
F23: =0 | G23: =0
C24: 계 | E24: =SUM(E19:E23) | F24: =SUM(F19:F23) | G24: =SUM(G19:G23) | H24: =SUM(H19:H23)
B25: =B9 | E25: =SUM(F25:G25) | F25: =0
B26: =B10 | E26: =SUM(F26:G26) | F26: =0
B27: =B11 | E27: =SUM(F27:G27) | F27: =0
B28: =B12 | E28: =SUM(F28:G28) | F28: =0

Sheet 4. 원리금상환계획
B2: 4. 원리금 상환계획
B4: 가. 상환계획 종합
G5: (단위 : 천원)
B6: 연도 | C6: 융자금액 | D6: 원리금 상환액 | F6: 연말융자잔액 | G6: 비고
D7: 원금상환 | E7: 이자
B8: =C38 | C8: =C42 | D8: =E42 | E8: =D42 | F8: =C8-D8
B9: =B8+1 | C9: =C43 | D9: =E43 | E9: =D43 | F9: =C9-D9
B10: =B9+1 | C10: =C44 | D10: =E44 | E10: =D44 | F10: =C10-D10
B11: =B10+1 | C11: =C45 | D11: =E45 | E11: =D45 | F11: =C11-D11
B12: =B11+1 | C12: =C46 | D12: =E46 | E12: =D46 | F12: =C12-D12
B13: =B12+1 | C13: =C47 | D13: =E47 | E13: =D47 | F13: =C13-D13
B14: =B13+1 | C14: =C48 | D14: =E48 | E14: =D48 | F14: =C14-D14
B15: =B14+1 | C15: =C49 | D15: =E49 | E15: =D49 | F15: =C15-D15
B16: =B15+1 | C16: =C50 | D16: =E50 | E16: =D50 | F16: =C16-D16
B17: =B16+1 | C17: =C51 | D17: =E51 | E17: =D51 | F17: =C17-D17
B18: =B17+1 | C18: =C52 | D18: =E52 | E18: =D52 | F18: =C18-D18
B19: =B18+1 | C19: =C53 | D19: =E53 | E19: =D53 | F19: =C19-D19
B20: =B19+1 | C20: =C54 | D20: =E54 | E20: =D54 | F20: =C20-D20
... B32: =B31+1 | C32: =C66 | D32: =E66 | E32: =D66 | F32: =C32-D32
B35: 나. 융자 종류별 원리금 상환계획
G36: (단위 : 천원)
B37: 종류 | C37: 융자시기 | D37: 융자액 | E37: 융자조건 | F37: 연이자율 | G37: 균등분할상환액
D38: ='3.투자계획'!F8 | G38: =-PMT(F38,20,D38,0,0) | H38: PMT함수 = (이자율,상환기간, 현재가치(대출금액),미래가치(잔액 0), 타입(후불제(0) 원리금상환인경우),
G39: (단위 : 천원)
B40: 연차 | C40: 연초융자잔액 | D40: 상환원리금 | G40: 비고
D41: 이자 | E41: 원금상환 | F41: 계
B42: =B8 | C42: =D38 | D42: =C42*$F$38 | F42: =D42+E42
B43: =B9 | C43: =C42 | D43: =C43*$F$38 | F43: =D43+E43
B44: =B10 | C44: =C43 | D44: =C44*$F$38 | F44: =D44+E44
B45: =B11 | C45: =C44 | D45: =C45*$F$38 | F45: =D45+E45
B46: =B12 | C46: =C45 | D46: =C46*$F$38 | F46: =D46+E46
B47: =B13 | C47: =C46 | D47: =C47*$F$38 | E47: =F47-D47 | F47: =G38
B48: =B14 | C48: =C47-E47 | D48: =C48*$F$38 | E48: =F48-D48 | F48: =F47
B49: =B15 | C49: =C48-E48 | D49: =C49*$F$38 | E49: =F49-D49 | F49: =F48
B50: =B16 | C50: =C49-E49 | D50: =C50*$F$38 | E50: =F50-D50 | F50: =F49
B51: =B17 | C51: =C50-E50 | D51: =C51*$F$38 | E51: =F51-D51 | F51: =F50
B52: =B18 | C52: =C51-E51 | D52: =C52*$F$38 | E52: =F52-D52 | F52: =F51
B53: =B19 | C53: =C52-E52 | D53: =C53*$F$38 | E53: =F53-D53 | F53: =F52
B54: =B20 | C54: =C53-E53 | D54: =C54*$F$38 | E54: =F54-D54 | F54: =F53
B55: =B21 | C55: =C54-E54 | D55: =C55*$F$38 | E55: =F55-D55 | F55: =F54
...

Sheet  5. 판매계획
B2: 5. 판매계획
B4: 가. 연도별 가격 추이
O5: (단위 : 원/kg)
B6: 연도별 | C6: 등급 | E6: =G6-1 | G6: =I6-1 | I6: =K6-1 | K6: =M6-1 | O6: 평균가격
B7: 평균가격(수매) | C7: 상 품 | O7: =AVERAGE(E7:N9)
C8: 중 품
C9: 하 품
B10: 연도별 | C10: 등급 | O10: 평균가격
B11: 평균가격(직거래) | C11: 상 품 | O11: =AVERAGE(E11:N13)
B17: 나. 유통채널별 판매계획
O18: (단위 : %, kg)
B19: 유통채널 | C19: 등급 | N19: 비고
D20: 판매비율 | E20: 판매량 | F20: 판매비율 | G20: 판매량 | H20: 판매비율 | I20: 판매량 | J20: 판매비율 | K20: 판매량 | L20: 판매비율 | M20: 판매량
B22: 수매시장 | C22: 상품 | E22: =D22*'6. 생산계획'!$H$9 | G22: =F22*'6. 생산계획'!$K$9 | I22: =H22*'6. 생산계획'!$N$9 | K22: =J22*'6. 생산계획'!$Q$9 | M22: =L22*'6. 생산계획'!$T$9
C23: 중품 | E23: =D23*'6. 생산계획'!$H$9 | G23: =F23*'6. 생산계획'!$K$9 | I23: =H23*'6. 생산계획'!$N$9 | K23: =J23*'6. 생산계획'!$Q$9 | M23: =L23*'6. 생산계획'!$T$9
C24: 하품 | E24: =D24*'6. 생산계획'!$H$9 | G24: =F24*'6. 생산계획'!$K$9 | I24: =H24*'6. 생산계획'!$N$9 | K24: =J24*'6. 생산계획'!$Q$9 | M24: =L24*'6. 생산계획'!$T$9
C25: 계 | D25: =SUM(D22:D24) | E25: =SUM(E22:E24) | F25: =SUM(F22:F24) | G25: =SUM(G22:G24) | H25: =SUM(H22:H24) | I25: =SUM(I22:I24) | J25: =SUM(J22:J24) | K25: =SUM(K22:K24) | ... M25: =SUM(M22:M24)
B26: 직거래 | C26: 상품 | E26: =D26*'6. 생산계획'!$H$9 | G26: =F26*'6. 생산계획'!$K$9 | I26: =H26*'6. 생산계획'!$N$9 | K26: =J26*'6. 생산계획'!$Q$9 | M26: =L26*'6. 생산계획'!$T$9
C27: 중품 | E27: =D27*'6. 생산계획'!$H$9 | G27: =F27*'6. 생산계획'!$K$9 | I27: =H27*'6. 생산계획'!$N$9 | K27: =J27*'6. 생산계획'!$Q$9 | M27: =L27*'6. 생산계획'!$T$9
C28: 하품 | E28: =D28*'6. 생산계획'!$H$9 | G28: =F28*'6. 생산계획'!$K$9 | I28: =H28*'6. 생산계획'!$N$9 | K28: =J28*'6. 생산계획'!$Q$9 | M28: =L28*'6. 생산계획'!$T$9
C29: 계 | D29: =SUM(D26:D28) | E29: =SUM(E26:E28) | F29: =SUM(F26:F28) | G29: =SUM(G26:G28) | H29: =SUM(H26:H28) | I29: =SUM(I26:I28) | J29: =SUM(J26:J28) | K29: =SUM(K26:K28) | ... M29: =SUM(M26:M28)
B30: 미상품과 | D30: =100%-D25-D29 | E30: =D30*'6. 생산계획'!$H$9 | F30: =100%-F25-F29 | G30: =F30*'6. 생산계획'!$K$9 | H30: =100%-H25-H29 | I30: =H30*'6. 생산계획'!$N$9 | J30: =100%-J25-J29 | K30: =J30*'6. 생산계획'!$Q$9 | L30: =100%-L25-L29 | M30: =L30*'6. 생산계획'!$T$9
B31: 합 계 | D31: =D25+D29+D30 | E31: =E25+E29+E30 | F31: =F25+F29+F30 | G31: =G25+G29+G30 | H31: =H25+H29+H30 | I31: =I25+I29+I30 | J31: =J25+J29+J30 | K31: =K25+K29+K30 | ... M31: =M25+M29+M30
B34: 다. 연도별 매출액 추정
M35: (단위 : 천원, Kg)
M36: 비고
C37: 수량 | D37: 매출액 | E37: 수량 | F37: 매출액 | G37: 수량 | H37: 매출액 | I37: 수량 | J37: 매출액 | K37: 수량 | L37: 매출액
B38: 수매(상품) | C38: =E22 | D38: =C38*$O$7/1000 | E38: =G22 | F38: =E38*$O$7/1000 | G38: =I22 | H38: =G38*$O$7/1000 | I38: =K22 | J38: =I38*$O$7/1000 | K38: =M22 | L38: =K38*$O$7/1000
B39: 수매(중품) | C39: =E23 | D39: =C39*$O$8/1000 | E39: =G23 | F39: =E39*$O$8/1000 | G39: =I23 | H39: =G39*$O$8/1000 | I39: =K23 | J39: =I39*$O$8/1000 | K39: =M23 | L39: =K39*$O$8/1000
B40: 수매(하품) | C40: =E24 | D40: =C40*$O$9/1000 | E40: =G24 | F40: =E40*$O$9/1000 | G40: =I24 | H40: =G40*$O$9/1000 | I40: =K24 | J40: =I40*$O$9/1000 | K40: =M24 | L40: =K40*$O$9/1000
B41: 직거래(상품) | C41: =E26 | D41: =C41*$O$11/1000 | E41: =G26 | F41: =E41*$O$11/1000 | G41: =I26 | H41: =G41*$O$11/1000 | I41: =K26 | J41: =I41*$O$11/1000 | K41: =M26 | L41: =K41*$O$11/1000
B42: 직거래(중품) | C42: =E27 | D42: =C42*$O$12/1000 | E42: =G27 | F42: =E42*$O$12/1000 | G42: =I27 | H42: =G42*$O$12/1000 | I42: =K27 | J42: =I42*$O$12/1000 | K42: =M27 | L42: =K42*$O$12/1000
B43: 직거래(하품) | C43: =E28 | D43: =C43*$O$13/1000 | E43: =G28 | F43: =E43*$O$13/1000 | G43: =I28 | H43: =G43*$O$13/1000 | I43: =K28 | J43: =I43*$O$13/1000 | K43: =M28 | L43: =K43*$O$13/1000
B44: 판매금액 | C44: =SUM(D38:D43) | E44: =SUM(F38:F43) | G44: =SUM(H38:H43) | I44: =SUM(J38:J43) | K44: =SUM(L38:L43)

Sheet 6. 생산계획
B2: 6. 생산계획
B4: 가. 생산량계획
B6: 구 분 | W6: 비고
B7: 10a당 생산량(kg) | H7: =H9/5520*1000 | K7: =K9/5520*1000 | N7: =N9/5520*1000 | Q7: =Q9/5520*1000 | T7: =T9/5520*1000
B8: 재배면적(㎡)
B9: 생산량(kg) | K9: =2160+8400 | N9: =K9*1.05 | Q9: =N9*1.05 | T9: =Q9
B12: 나. 생산량 산출근거
B14: 항목 | H14: 세부사항
B15: 재배면적
B17: 묘목수
B19: 생산량 | E19: 시설(1년차)
E21: 시설(2년차 이후)
B23: 생산증가율
B24: 상품화율
B25: 합계 | E25: 묘목수(1년차)
E26: 생산량(1년차)
E27: 묘목수(2년차 이후)
E28: 생산량(2년차 이후)

Sheet 7. 영농자재소요계획
B2: 7. 영농자재 소요계획
B4: 적용기준 | C4: 묘목비(원/10a) | D4: 무기질비료비(원/10a) | E4: 유기질비료비(원/10a) | F4: 작물보호제비(원/10a) | G4: 산출근거 | J4: 지역별 농산물 소득자료
G5: 자료조사를 통한 적정 시비량 계산
B6: 참고자료
C7: * 작물보호제비는 농사로 병해충방제정보 PLS 허용품목에 한하여 가격조사
B13: 가. 1년차
B15: 비 목 | C15: 비용/10a | D15: 재배면적(㎡) | E15: 산출기준 | G15: 금 액(천원)
B16: 종자비 | C16: =$C$5*1.025*1.025*1.025 | G16: =C16*6.61/1000
B17: 무기질비료비 | C17: =$D$5*1.025*1.025*1.025 | G17: =C17*6.61/1000
B18: 유기질비료비 | C18: =$E$5*1.025*1.025*1.025 | G18: =C18*6.61/1000
B19: 작물보호제비 | C19: =$F$5*1.025*1.025*1.025 | G19: =C19*6.61/1000
B20: 기타재료비
B21: 합계 | G21: =SUM(G16:G20)
B23: 나. 2년차
B25: 비 목 | C25: 비용/10a | D25: 재배면적(㎡) | E25: 산출기준 | G25: 금 액(천원)
B26: 종자비 | C26: =C16*0 | G26: =C26*5.52/1000
B27: 무기질비료비 | C27: =C17*1.025 | G27: =C27*6.61/1000
B28: 유기질비료비 | C28: =C18*1.025 | G28: =C28*6.61/1000
B29: 작물보호제비 | C29: =C19*1.025 | G29: =C29*6.61/1000
B30: 기타재료비
B31: 합계 | G31: =SUM(G26:G30)
B33: 다. 3년차
B35: 비 목 | C35: 비용/10a | D35: 재배면적(㎡) | E35: 산출기준 | G35: 금 액(천원)
B36: 종자비 | C36: =C26*1.025 | G36: =C36*5.52/1000
B37: 무기질비료비 | C37: =C27*1.025 | G37: =C37*6.61/1000
B38: 유기질비료비 | C38: =C28*1.025 | G38: =C38*6.61/1000
B39: 작물보호제비 | C39: =C29*1.025 | G39: =C39*6.61/1000
B40: 기타재료비
B41: 합계 | G41: =SUM(G36:G40)
B43: 라. 4년차
B45: 비 목 | C45: 비용/10a | D45: 재배면적(㎡) | E45: 산출기준 | G45: 금 액(천원)
B46: 종자비 | C46: =C36*1.025 | G46: =C46*5.52/1000
B47: 무기질비료비 | C47: =C37*1.025 | G47: =C47*6.61/1000
B48: 유기질비료비 | C48: =C38*1.025 | G48: =C48*6.61/1000
B49: 작물보호제비 | C49: =C39*1.025 | G49: =C49*6.61/1000
B50: 기타재료비
B51: 합계 | G51: =SUM(G46:G50)
B53: 마. 5년차
B55: 비 목 | C55: 비용/10a | D55: 재배면적(㎡) | E55: 산출기준 | G55: 금 액(천원)
B56: 종자비 | C56: =C46*1.025 | G56: =C56*5.52/1000
...

Sheet 8. 노무비계획
B2: 8. 노무비계획
B4: 가. 노동력 소요 및 노무비 계획
T5: (단위:일수,천원)
B6: 구 분 | U6: 비 고
F7: 일당(원) | G7: 작업 일수 | H7: 금액 | I7: 일당(원) | J7: 작업 일수 | K7: 금액 | L7: 일당(원) | M7: 작업 일수 | N7: 금액 | O7: 일당(원) | P7: 작업 일수 | Q7: 금액 | R7: 일당(원) | S7: 작업 일수 | T7: 금액
B8: 자가 노동비 | C8: 본인 | F8: =Y34 | G8: =365*0.5*0.9 | H8: =F8*G8/1000 | I8: =F8*(1+$AC$38) | J8: =365*0.6*0.9 | K8: =I8*J8/1000 | L8: =I8*(1+$AC$38) | M8: =J8 | N8: =L8*M8/1000 | O8: =L8*(1+$AC$38) | P8: =J8 | Q8: =O8*P8/1000 | R8: =O8*(1+$AC$38) | S8: =P8 | T8: =R8*S8/1000
C9: 가족
C10: 소계 | F10: =F8+F9 | G10: =G8 | H10: =H8+H9 | I10: =I8+I9 | J10: =J8 | K10: =K8+K9 | L10: =L8+L9 | M10: =M8 | N10: =N8+N9 | O10: =O8+O9 | P10: =P8 | Q10: =Q8+Q9 | R10: =R8+R9 | S10: =S8 | T10: =T8+T9
B11: 고용 노동비 | C11: 일용직 | D11: 잡급 | E11: 남 | F11: =Y34 | H11: =F11*G11/1000 | I11: =F11*(1+$AC$38) | K11: =I11*J11/1000 | L11: =I11*(1+$AC$38) | N11: =L11*M11/1000 | O11: =L11*(1+$AC$38) | Q11: =O11*P11/1000 | R11: =O11*(1+$AC$38) | T11: =R11*S11/1000
E12: 여 | F12: =Z34 | H12: =F12*G12/1000 | I12: =F12*(1+$AD$38) | K12: =I12*J12/1000 | L12: =I12*(1+$AD$38) | N12: =L12*M12/1000 | O12: =L12*(1+$AD$38) | Q12: =O12*P12/1000 | R12: =O12*(1+$AD$38) | T12: =R12*S12/1000
C13: 소계 | F13: =F11+F12 | H13: =H11+H12 | I13: =I11+I12 | J13: =J11+J12 | K13: =K11+K12 | L13: =L11+L12 | M13: =M11+M12 | N13: =N11+N12 | O13: =O11+O12 | Q13: =Q11+Q12 | R13: =R11+R12 | S13: =S11+S12 | T13: =T11+T12
C14: 상용직 | D14: 급여
D15: 상여금
D16: 퇴직 급여
B22: 나. 노동비 산출근거(1년차)
B24: 항목 | I24: 작업일수 | K24: 자가 노동비 | O24: 고용(남자, 단가 동일) | R24: 고용(여자) | X24: 인건비 평균 상승률(5년평균)
K25: 일수 | L25: 단가 | N25: 계(천원) | O25: 일수 | P25: 계(천원) | R25: 일수 | S25: 단가 | U25: 계(천원) | Y25: 남자 | Z25: 여자 | AB25: 인상율
B26: 경운 | L26: =Y34 | N26: =K26*L26/1000 | O26: =0 | P26: =Y34 | R26: =0 | S26: =Z32 | U26: =R26*S26/1000 | W26: 자료집 | AB26: =X26+1 | AC26: =(Y27-Y26)/Y26 | AD26: =(Z27-Z26)/Z26
B27: 파종 | L27: =L26 | N27: =K27*L27/1000 | O27: =0 | P27: =P26 | R27: =0 | S27: =S26 | U27: =R27*S27/1000 | X27: =X26+1 | Z27: =Z28 | AB27: =AB26+1 | AC27: =(Y28-Y27)/Y27 | AD27: =(Z28-Z27)/Z27
B28: 정식 | L28: =L27 | N28: =K28*L28/1000 | O28: =0 | P28: =P27 | R28: =0 | S28: =S27 | U28: =R28*S28/1000 | X28: =X27+1 | AB28: =AB27+1 | AC28: =(Y29-Y28)/Y28 | AD28: =(Z29-Z28)/Z28
L29: =L28 | N29: =K29*L29/1000 | O29: =0 | P29: =P28 | R29: =0 | S29: =S28 | U29: =R29*S29/1000 | X29: =X28+1 | AB29: =AB28+1 | AC29: =(Y30-Y29)/Y29 | AD29: =(Z30-Z29)/Z29
B30: 웃거름주기 및 작물보호제 살포 | L30: =L29 | N30: =K30*L30/1000 | O30: =0 | P30: =P29 | R30: =0 | S30: =S29 | U30: =R30*S30/1000 | X30: =X29+1 | AB30: =AB29+1 | AC30: =(Y31-Y30)/Y30 | AD30: =(Z31-Z30)/Z30
L31: =L30 | N31: =K31*L31/1000 | O31: =0 | P31: =P30 | R31: =0 | S31: =S30 | U31: =R31*S31/1000 | X31: =X30+1 | AB31: =AB30+1
B32: 제초작업 및 유지 관리 | L32: =L31 | N32: =K32*L32/1000 | O32: =0 | P32: =P31 | R32: =0 | S32: =S31 | U32: =R32*S32/1000 | W32: 예측치 | X32: =X31+1 | Y32: =Y31+Y31*$AC$38 | Z32: =Z31+Z31*$AD$38 | AB32: =AB31+1
B33: 수확 및 선별 | L33: =L32 | N33: =K33*L33/1000 | P33: =P32 | S33: =S32 | U33: =R33*S33/1000 | X33: =X32+1 | Y33: =Y32+Y32*$AC$38 | Z33: =Z32+Z32*$AD$38 | AB33: =AB32+1
B34: 합계 | I34: =SUM(I26:J33) | K34: =SUM(K26:K33) | N34: =SUM(N26:N33) | O34: =SUM(O26:O33) | R34: =R33 | S34: =F12 | U34: =U33 | X34: =X33+1 | Y34: =Y33+Y33*$AC$38 | Z34: =Z33+Z33*$AD$38 | AB34: =AB33+1
X35: =X34+1 | Y35: =Y34+Y34*$AC$38 | Z35: =Z34+Z34*$AD$38 | AB35: =AB34+1
B36: 다. 노동비 산출근거(2년차 이후, 임금은 매년 상승) | X36: =X35+1 | Y36: =Y35+Y35*$AC$38 | Z36: =Z35+Z35*$AD$38 | AB36: =AB35+1
X37: =X36+1 | Y37: =Y36+Y36*$AC$38 | Z37: =Z36+Z36*$AD$38 | AB37: =AB36+1
B38: 항목 | I38: 작업일수 | K38: 자가 노동비 | O38: 고용(남자, 단가 동일) | R38: 고용(여자) | X38: =X37+1 | Y38: =Y37+Y37*$AC$38 | Z38: =Z37+Z37*$AD$38 | AB38: 평균 | AC38: =AVERAGE(AC26:AC37) | AD38: =AVERAGE(AD26:AD37)
K39: 일수 | L39: 단가 | N39: 계(천원) | O39: 일수 | P39: 계(천원) | R39: 일수 | S39: 단가 | U39: 계(천원)
B40: 경운 | L40: =Y35 | N40: =K40*L40/1000 | O40: =0 | P40: =Y35 | R40: =0 | S40: =Z35 | U40: =R40*S40/1000
B41: 파종 | L41: =L40 | N41: =K41*L41/1000 | O41: =0 | P41: =P40 | R41: =0 | S41: =S40 | U41: =R41*S41/1000
B42: 정식 | L42: =L41 | N42: =K42*L42/1000 | O42: =0 | P42: =P41 | R42: =0 | S42: =S41 | U42: =R42*S42/1000
L43: =L42 | N43: =K43*L43/1000 | O43: =0 | P43: =P42 | R43: =0 | S43: =S42 | U43: =R43*S43/1000
B44: 웃거름주기 및 작물보호제 살포 | L44: =L43 | N44: =K44*L44/1000 | O44: =0 | P44: =P43 | R44: =0 | S44: =S43 | U44: =R44*S44/1000
L45: =L44 | N45: =K45*L45/1000 | O45: =0 | P45: =P44 | R45: =0 | S45: =S44 | U45: =R45*S45/1000
B46: 제초작업 및 유지 관리 | L46: =L45 | N46: =K46*L46/1000 | O46: =0 | P46: =P45 | R46: =0 | S46: =S45 | U46: =R46*S46/1000
B47: 수확 및 선별 | L47: =L46 | N47: =K47*L47/1000 | P47: =P46 | S47: =S46 | U47: =R47*S47/1000
B48: 합계 | I48: =SUM(I40:J47) | K48: =SUM(K40:K47) | N48: =SUM(N40:N47) | O48: =SUM(O40:O47) | P48: =P47 | R48: =R47 | S48: =I12 | U48: =U47

Sheet 9 .경비계획
B2: 9. 경비계획
B4: 항목 | D4: 기준 | E4: 비고
B5: 대농기구 수선비
B6: 영농시설 수선비
B7: 수도광열비 (천원/10a)
B8: 경영면적(m2) > 1년차
B9: 경영면적(m2) > 2년차 이후
B10: 임대면적(m2)
B12: 가. 1년차
E13: (단위 : 천원)
B14: 과 목 | C14: 금 액 | D14: 산 출 근 거 | E14: 비고
B15: 1. 수선비 | C15: =SUM(C16:C17)
B16: 가. 영농시설 | C16: ='10. 감가상각비계획 '!G8*'9 .경비계획'!D6
B17: 나. 대농기구 | C17: ='10. 감가상각비계획 '!I8*'9 .경비계획'!D5
B18: 2. 수도 광열비 | C18: =D7*6611/1000*1.025*1.025*1.025
B20: 3. 감가상각비 | C20: =SUM(C21:C22:C23) | D20: * 감가상각비계획 참조
B21: 가. 영농시설 | C21: ='10. 감가상각비계획 '!G12
B22: 나. 대농기구 | C22: ='10. 감가상각비계획 '!I12
B23: 다. 생물자산 | C23: ='10. 감가상각비계획 '!K12
B24: 4. 임차료 | C24: =SUM(C25:C26)
B25: 가. 대농기구 | D25: * 연간 농기계 임차료(개인)
B26: 나. 토지 | C26: =1470/3.3*0+1260/3.3*0
B27: 5. 위탁영농비 | C27: =0
B28: 6. 소농구비 | C28: =0
B29: 7. 기타 요금 | C29: =0
B30: 합 계 | C30: =C15+C18+C20+C24+C27+C28+C29
B32: 나. 2년차
B34: 과 목 | C34: 금 액 | D34: 산 출 근 거 | E34: 비고
B35: 1. 수선비 | C35: =SUM(C36:C37)
B36: 가. 영농시설 | C36: =C16
B37: 나. 대농기구 | C37: =C17
B38: 2. 수도 광열비 | C38: =C18*1.025
B40: 3. 감가상각비 | C40: =SUM(C41:C42:C43) | D40: * 감가상각비계획 참조
B41: 가. 영농시설 | C41: ='10. 감가상각비계획 '!G24
B42: 나. 대농기구 | C42: ='10. 감가상각비계획 '!I24
B43: 다. 생물자산 | C43: ='10. 감가상각비계획 '!K24
B44: 4. 임차료 | C44: =SUM(C45:C46)
B45: 가. 대농기구 | D45: * 연간 농기계 임차료(개인)
B46: 나. 토지
B47: 5. 위탁영농비 | C47: =0
...

Sheet 10. 감가상각비계획 
B2: 10. 감가상각비계획
B4: 가. 1년차
J5: (단위 : 천원)
B6: 구 분 | C6: 영농시설 | H6: 대농기구 | J6: 생물 자산
C7: ='3.투자계획'!C20 | D7: ='3.투자계획'!C21 | E7: ='3.투자계획'!C22 | F7: ='3.투자계획'!C23 | G7: 계 | H7: ='3.투자계획'!C19 | I7: 계
B8: 취 득 가 격 | C8: ='3.투자계획'!E20 | D8: ='3.투자계획'!E21 | E8: ='3.투자계획'!E22 | F8: ='3.투자계획'!E23 | G8: =SUM(C8:F8) | H8: ='3.투자계획'!E19 | I8: =SUM(H8:H8)
B9: 잔 존 가 격 율
B10: 내 용 년 수(년)
B11: 사 용 년 수(년)
B12: 감 가 상 각 비 | C12: =C8/C10 | D12: =D8/D10 | E12: =E8/E10 | F12: =F8/F10 | G12: =SUM(C12:F12) | H12: =(H8-H8*0.1)/H10 | I12: =SUM(H12:H12)
B13: 감 가 상 각 누 계 | C13: =C11*C12 | D13: =D11*D12 | E13: =E11*E12 | F13: =F11*F12 | G13: =SUM(C13:F13) | H13: =H11*H12 | I13: =SUM(H13:H13)
B14: 장 부 가 격 | C14: =C8-C13 | D14: =D8-D13 | E14: =E8-E13 | F14: =F8-F13 | G14: =SUM(C14:F14) | H14: =H8-H13 | I14: =SUM(H14:H14)
B16: 나. 2년차
J17: (단위 : 천원)
B18: 구 분 | C18: 영농시설 | H18: 대농기구 | J18: 생물 자산
C19: =C7 | D19: =D7 | E19: =E7 | F19: =F7 | G19: 계 | I19: 계
B20: 취 득 가 격 | C20: =C8 | D20: =D8 | E20: =E8 | F20: =F8 | G20: =SUM(C20:F20) | I20: =SUM(H20:H20)
B21: 잔 존 가 격 율 | C21: =C9 | D21: =D9 | E21: =E9 | F21: =F9 | H21: =H9
B22: 내 용 년 수(년) | C22: =C10 | D22: =D10 | E22: =E10 | F22: =F10 | H22: =H10
B23: 사 용 년 수(년) | C23: =C11+1 | D23: =D11+1 | E23: =E11+1 | F23: =F11+1 | H23: =H11+1
B24: 감 가 상 각 비 | C24: =C20/C22 | D24: =D20/D22 | E24: =E20/E22 | F24: =F20/F22 | G24: =SUM(C24:F24) | H24: =(H20-H20*0.1)/H22 | I24: =SUM(H24:H24)
B25: 감 가 상 각 누 계 | C25: =C23*C24 | D25: =D23*D24 | E25: =E23*E24 | F25: =F23*F24 | G25: =SUM(C25:F25) | H25: =H23*H24 | I25: =SUM(H25:H25)
B26: 장 부 가 격 | C26: =C20-C25 | D26: =D20-D25 | E26: =E20-E25 | F26: =F20-F25 | G26: =SUM(C26:F26) | H26: =H20-H25 | I26: =SUM(H26:H26)
B28: 다. 3년차
J29: (단위 : 천원)
B30: 구 분 | C30: 영농시설 | H30: 대농기구 | J30: 생물 자산
C31: =C19 | D31: =D19 | E31: =E19 | F31: =F19 | G31: 계 | I31: 계
B32: 취 득 가 격 | C32: =C20 | D32: =D20 | E32: =E20 | F32: =F20 | G32: =SUM(C32:F32) | I32: =SUM(H32:H32)
B33: 잔 존 가 격 율 | C33: =C21 | D33: =D21 | E33: =E21 | F33: =F21 | H33: =H21
B34: 내 용 년 수(년) | C34: =C22 | D34: =D22 | E34: =E22 | F34: =F22 | H34: =H22
B35: 사 용 년 수(년) | C35: =C23+1 | D35: =D23+1 | E35: =E23+1 | F35: =F23+1 | H35: =H23+1
B36: 감 가 상 각 비 | C36: =C32/C34 | D36: =D32/D34 | E36: =E32/E34 | F36: =F32/F34 | G36: =SUM(C36:F36) | H36: =(H32-H32*0.1)/H34 | I36: =SUM(H36:H36)
B37: 감 가 상 각 누 계 | C37: =C35*C36 | D37: =D35*D36 | E37: =E35*E36 | F37: =F35*F36 | G37: =SUM(C37:F37) | H37: =H35*H36 | I37: =SUM(H37:H37)
B38: 장 부 가 격 | C38: =C32-C37 | D38: =D32-D37 | E38: =E32-E37 | F38: =F32-F37 | G38: =SUM(C38:F38) | H38: =H32-H37 | I38: =SUM(H38:H38)
B40: 라. 4년차
J41: (단위 : 천원)
B42: 구 분 | C42: 영농시설 | H42: 대농기구 | J42: 생물 자산
C43: =C31 | D43: =D31 | E43: =E31 | F43: =F31 | G43: 계 | I43: 계
B44: 취 득 가 격 | C44: =C32 | D44: =D32 | E44: =E32 | F44: =F32 | G44: =SUM(C44:F44) | I44: =SUM(H44:H44)
B45: 잔 존 가 격 율 | C45: =C33 | D45: =D33 | E45: =E33 | F45: =F33 | H45: =H33
...

Sheet 11. 생산원가계획
B2: 11. 생산원가계획
G3: (단위 : 천원)
B4: 과 목
B5: I. 재료비 | C5: =SUM(C6:C10) | D5: =SUM(D6:D10) | E5: =SUM(E6:E10) | F5: =SUM(F6:F10) | G5: =SUM(G6:G10)
B6: 1. 종자비 | C6: ='7. 영농자재소요계획'!G16 | D6: ='7. 영농자재소요계획'!G26 | E6: ='7. 영농자재소요계획'!G36 | F6: ='7. 영농자재소요계획'!G46 | G6: ='7. 영농자재소요계획'!G56
B7: 2. 무기질비료비 | C7: ='7. 영농자재소요계획'!G17 | D7: ='7. 영농자재소요계획'!G27 | E7: ='7. 영농자재소요계획'!G37 | F7: ='7. 영농자재소요계획'!G47 | G7: ='7. 영농자재소요계획'!G57
B8: 3. 유기질비료비 | C8: ='7. 영농자재소요계획'!G18 | D8: ='7. 영농자재소요계획'!G28 | E8: ='7. 영농자재소요계획'!G38 | F8: ='7. 영농자재소요계획'!G48 | G8: ='7. 영농자재소요계획'!G58
B9: 4. 작물보호제비 | C9: ='7. 영농자재소요계획'!G19 | D9: ='7. 영농자재소요계획'!G29 | E9: ='7. 영농자재소요계획'!G39 | F9: ='7. 영농자재소요계획'!G49 | G9: ='7. 영농자재소요계획'!G59
B10: 5. 기타재료비 | C10: ='7. 영농자재소요계획'!G20 | D10: ='7. 영농자재소요계획'!G30 | E10: ='7. 영농자재소요계획'!G40 | F10: ='7. 영농자재소요계획'!G50 | G10: ='7. 영농자재소요계획'!G60
B11: II. 노무비 | C11: =SUM(C12:C15) | D11: =SUM(D12:D15) | E11: =SUM(E12:E15) | F11: =SUM(F12:F15) | G11: =SUM(G12:G15)
B12: 1. 급여 | C12: ='8. 노무비계획'!H10 | D12: ='8. 노무비계획'!K10 | E12: ='8. 노무비계획'!N10 | F12: ='8. 노무비계획'!Q10 | G12: ='8. 노무비계획'!T10
B13: 2. 상여금 | C13: =0 | D13: =0 | E13: =0 | F13: =0 | G13: =0
B14: 3. 퇴직급여 | C14: =0 | D14: =0 | E14: =0 | F14: =0 | G14: =0
B15: 4. 잡급 | C15: ='8. 노무비계획'!H13 | D15: ='8. 노무비계획'!K13 | E15: ='8. 노무비계획'!N13 | F15: ='8. 노무비계획'!Q13 | G15: ='8. 노무비계획'!T13
B16: III. 경비 | C16: =C17+C20+C25+C21+C29+C30 | D16: =D17+D20+D25+D21+D29+D30 | E16: =E17+E20+E25+E21+E29+E30 | F16: =F17+F20+F25+F21+F29+F30 | G16: =G17+G20+G25+G21+G29+G30
B17: 1. 수선비 | C17: =SUM(C18:C19) | D17: =SUM(D18:D19) | E17: =SUM(E18:E19) | F17: =SUM(F18:F19) | G17: =SUM(G18:G19)
B18: 가. 영농시설 | C18: ='9 .경비계획'!$C16 | D18: ='9 .경비계획'!$C36 | E18: ='9 .경비계획'!$C56 | F18: ='9 .경비계획'!$C76 | G18: ='9 .경비계획'!$C96
B19: 나. 대농기구 | C19: ='9 .경비계획'!C17 | D19: ='9 .경비계획'!C37 | E19: ='9 .경비계획'!C57 | F19: ='9 .경비계획'!C77 | G19: ='9 .경비계획'!C97
B20: 2. 수도광열비 | C20: ='9 .경비계획'!C18 | D20: ='9 .경비계획'!C38 | E20: ='9 .경비계획'!C58 | F20: ='9 .경비계획'!C78 | G20: ='9 .경비계획'!C98
B21: 3. 감가상각비 | C21: =SUM(C22:C24) | D21: =SUM(D22:D24) | E21: =SUM(E22:E24) | F21: =SUM(F22:F24) | G21: =SUM(G22:G24)
B22: 가. 영농시설 | C22: ='10. 감가상각비계획 '!G12 | D22: ='10. 감가상각비계획 '!G24 | E22: ='10. 감가상각비계획 '!G36 | F22: ='10. 감가상각비계획 '!G48 | G22: ='10. 감가상각비계획 '!G60
B23: 나. 대농기구 | C23: ='10. 감가상각비계획 '!I12 | D23: ='10. 감가상각비계획 '!I24 | E23: ='10. 감가상각비계획 '!I36 | F23: ='10. 감가상각비계획 '!I48 | G23: ='10. 감가상각비계획 '!I60
B24: 다. 생물 자산 | C24: ='10. 감가상각비계획 '!K12 | D24: ='10. 감가상각비계획 '!K24 | E24: ='10. 감가상각비계획 '!K36 | F24: ='10. 감가상각비계획 '!K48 | G24: ='10. 감가상각비계획 '!K60
B25: 4. 임차료 | C25: =SUM(C26:C27) | D25: =SUM(C26:C27) | E25: =SUM(C26:C27) | F25: =SUM(C26:C27) | G25: =SUM(C26:C27)
B26: 가. 대농기구 | C26: ='9 .경비계획'!C25 | D26: ='9 .경비계획'!C45 | E26: ='9 .경비계획'!C65 | F26: ='9 .경비계획'!C85 | G26: ='9 .경비계획'!C105
B27: 나. 토지 | C27: ='9 .경비계획'!C26 | D27: ='9 .경비계획'!C46 | E27: ='9 .경비계획'!C66 | F27: ='9 .경비계획'!C86 | G27: ='9 .경비계획'!C106
B28: 5. 위탁영농비 | G28: =0
B29: 6. 소농구비 | C29: ='9 .경비계획'!$C28 | D29: =0 | E29: =0 | F29: =0 | G29: =0
B30: 7. 기타 요금 | C30: ='9 .경비계획'!$C29 | D30: ='9 .경비계획'!$C29 | E30: ='9 .경비계획'!$C29 | F30: ='9 .경비계획'!$C29 | G30: ='9 .경비계획'!$C29
B31: IV. 당기총생산원가 | C31: =C5+C11+C16 | D31: =D5+D11+D16 | E31: =E5+E11+E16 | F31: =F5+F11+F16 | G31: =G5+G11+G16
B32: Ⅴ. 기초생장물재고액 | C32: =0 | D32: =0 | E32: =0 | F32: =0 | G32: =0
B33: Ⅵ. 기말생장물재고액 | C33: =0 | D33: =0 | E33: =0 | F33: =0 | G33: =0
B34: Ⅶ. 타계정대체액 | C34: =0 | D34: =0 | E34: =0 | F34: =0 | G34: =0
B35: Ⅷ. 당기생산물생산원가 | C35: =C31+C32-C33-C34 | D35: =D31 | E35: =E31+$C$38 | F35: =F31+$C$38 | G35: =G31+$C$38

Sheet 12 손익계획
B2: 12. 손익계획
G3: (단위:천원)
B4: 과목
C5: 1월1일~12월31일 | D5: 1월1일~12월31일 | E5: 1월1일~12월31일 | F5: 1월1일~12월31일 | G5: 1월1일~12월31일
B6: I. 매출액 | C6: =SUM(C7:C8) | D6: =SUM(D7:D8) | E6: =SUM(E7:E8) | F6: =SUM(F7:F8) | G6: =SUM(G7:G8)
B7: 1. 생산물 매출 | C7: =SUM(' 5. 판매계획'!C44:D44) | D7: =SUM(' 5. 판매계획'!E44:F44) | E7: =SUM(' 5. 판매계획'!G44:H44) | F7: =SUM(' 5. 판매계획'!I44:J44) | G7: =SUM(' 5. 판매계획'!K44:L44)
B8: 2. 부산물 매출 | C8: =0 | D8: =0 | E8: =0 | F8: =0 | G8: =0
B9: II. 매출원가 | C9: ='11. 생산원가계획'!C35 | D9: ='11. 생산원가계획'!D35 | E9: ='11. 생산원가계획'!E35 | F9: ='11. 생산원가계획'!F35 | G9: ='11. 생산원가계획'!G35
B10: III. 매출총이익 | C10: =C6-C9 | D10: =D6-D9 | E10: =E6-E9 | F10: =F6-F9 | G10: =G6-G9
B11: IV. 판매비와 관리비 | C11: =SUM(C12:C14) | D11: =SUM(D12:D14) | E11: =SUM(E12:E14) | F11: =SUM(F12:F14) | G11: =SUM(G12:G14)
B12: 1. 포장비
B13: 2. 운반비
B14: 3. 기타 | C14: =0 | D14: =0 | E14: =0 | F14: =0 | G14: =0
B15: V. 영업이익 | C15: =C10-C11 | D15: =D10-D11 | E15: =E10-E11 | F15: =F10-F11 | G15: =G10-G11
B16: VI. 영업외 수익 | C16: =0 | D16: =0 | E16: =0 | F16: =0 | G16: =0
B17: 1. 토지/농기계임대료 | C17: =0 | D17: =0 | E17: =0 | F17: =0 | G17: =0
B18: 2. 보조금 | C18: =0 | D18: =0 | E18: =0 | F18: =0 | G18: =0
B19: 3. 배당금 | C19: =0 | D19: =0 | E19: =0 | F19: =0 | G19: =0
B20: VII. 영업외 비용 | C20: =SUM(C21:C22) | D20: =SUM(D21:D22) | E20: =SUM(E21:E22) | F20: =SUM(F21:F22) | G20: =SUM(G21:G22)
B21: 1. 이자비용 | C21: ='4. 원리금상환계획'!$E8 | D21: ='4. 원리금상환계획'!$E9 | E21: ='4. 원리금상환계획'!$E10 | F21: ='4. 원리금상환계획'!$E11 | G21: ='4. 원리금상환계획'!$E12
B22: 2. 기타 | C22: =0 | D22: =0 | E22: =0 | F22: =0 | G22: =0
B23: VIII. 세금차감전 순익 | C23: =C15+C16-C20 | D23: =D15+D16-D20 | E23: =E15+E16-E20 | F23: =F15+F16-F20 | G23: =G15+G16-G20
B24: (경상이익)
B25: IX. 세금(법인세 등) | C25: =0 | D25: =0 | E25: =0 | F25: =0 | G25: =0
B26: X. 당기순이익 | C26: =C23-C25 | D26: =D23-D25 | E26: =E23-E25 | F26: =F23-F25 | G26: =G23-G25
B29: 포장비(원)
B30: 용기
B31: 합 | E31: =E30
B32: 택배박스
B33: 택배가격(10kg)
B35: 생산량(kg)
B36: 생산량(10kg당) | C36: =C35/10 | D36: =D35/10 | E36: =E35/10 | F36: =F35/10 | G36: =G35/10
B37: 택배개수(10kg) | C37: =C35/10 | D37: =D35/10 | E37: =E35/10 | F37: =F35/10 | G37: =G35/10

Sheet 13. 추정대차대조표
B2: 13. 추정대차대조표
H4: (단위 : 천원)
B5: 과 목
C6: 12월31일 현재 | D6: 12월31일 현재 | E6: 12월31일 현재 | F6: 12월31일 현재 | G6: 12월31일 현재 | H6: 12월31일 현재
B7: 자 산
B8: Ⅰ. 유동자산 | C8: =SUM(C9:C14) | D8: =SUM(D9:D10) | E8: =SUM(E9:E10) | F8: =SUM(F9:F10) | G8: =SUM(G9:G10) | H8: =SUM(H9:H10)
B9: (1) 당좌자산 | C9: ='1. 기초재무상태조사'!E39 | D9: ='14. 현금흐름계획'!D23 | E9: ='14. 현금흐름계획'!E23 | F9: ='14. 현금흐름계획'!F23 | G9: ='14. 현금흐름계획'!G23 | H9: ='14. 현금흐름계획'!H23
B10: (2) 재고자산 | C10: =0 | D10: =SUM(D11:D14) | E10: =SUM(E11:E14) | F10: =SUM(F11:F14) | G10: =SUM(G11:G14) | H10: =SUM(H11:H14)
B11: 1. 생산물 | C11: =0 | D11: =0 | E11: =0 | F11: =0 | G11: =0 | H11: =0
B12: 2. 생장물 | C12: =0 | D12: ='11. 생산원가계획'!C33 | E12: ='11. 생산원가계획'!D33 | F12: ='11. 생산원가계획'!E33 | G12: ='11. 생산원가계획'!F33 | H12: ='11. 생산원가계획'!G33
B13: 3. 원재료 | C13: =0 | D13: =0 | E13: =0 | F13: =0 | G13: =0 | H13: =0
B14: 4. 저장품 | C14: =0 | D14: =0 | E14: =0 | F14: =0 | G14: =0 | H14: =0
B15: Ⅱ. 비유동자산 | C15: =SUM(C16,C17,C20,C21) | D15: =SUM(D16,D17,D20,D21) | E15: =SUM(E16,E17,E20,E21) | F15: =SUM(F16,F17,F20,F21) | G15: =SUM(G16,G17,G20,G21) | H15: =SUM(H16,H17,H20,H21)
B16: 1. 토지 | C16: ='1. 기초재무상태조사'!E9 | D16: =C16 | E16: =D16 | F16: =E16 | G16: =F16 | H16: =G16
B17: 2. 설비자산 | C17: =C18+C19 | D17: =SUM(D18:D19) | E17: =SUM(E18:E19) | F17: =SUM(F18:F19) | G17: =SUM(G18:G19) | H17: =SUM(H18:H19)
B18: 농기계 | C18: =0 | D18: ='10. 감가상각비계획 '!I14 | E18: ='10. 감가상각비계획 '!I26 | F18: ='10. 감가상각비계획 '!I38 | G18: ='10. 감가상각비계획 '!I50 | H18: ='10. 감가상각비계획 '!I62
B19: 시설 | C19: =0 | D19: ='10. 감가상각비계획 '!G14 | E19: ='10. 감가상각비계획 '!G26 | F19: ='10. 감가상각비계획 '!G38 | G19: ='10. 감가상각비계획 '!G50 | H19: ='10. 감가상각비계획 '!G62
B20: 3. 생물자산 | C20: =0 | D20: ='10. 감가상각비계획 '!K14 | E20: ='10. 감가상각비계획 '!K26 | F20: ='10. 감가상각비계획 '!K38 | G20: ='10. 감가상각비계획 '!K50 | H20: ='10. 감가상각비계획 '!K62
B21: 4. 성장중인 생물자산 | C21: =0 | D21: =0 | E21: =0 | F21: =0 | G21: =0 | H21: =0
B22: 자산 총계 | C22: =C8+C15 | D22: =D8+D15 | E22: =E8+E15 | F22: =F8+F15 | G22: =G8+G15 | H22: =SUM(H8,H15)
B23: 부 채
B24: Ⅰ. 유동부채 | C24: =0 | D24: =0 | E24: =0 | F24: =0 | G24: =0 | H24: =0
B25: Ⅱ. 비유동 부채 | C25: ='1. 기초재무상태조사'!E58 | D25: ='4. 원리금상환계획'!F8 | E25: ='4. 원리금상환계획'!F9 | F25: ='4. 원리금상환계획'!F10 | G25: ='4. 원리금상환계획'!F11 | H25: ='4. 원리금상환계획'!F12
B26: 부채 총계 | C26: =SUM(C24:C25) | D26: =SUM(D24:D25) | E26: =SUM(E24:E25) | F26: =SUM(F24:F25) | G26: =SUM(G24:G25) | H26: =SUM(H24:H25)
B27: 자 본
B28: Ⅰ. 자본금 | C28: =C22 | D28: =C28 | E28: =D28 | F28: =E28 | G28: =F28 | H28: =G28
B29: Ⅱ. 자본잉여금 | C29: =0 | D29: ='14. 현금흐름계획'!$D$9 | E29: ='14. 현금흐름계획'!$D$9 | F29: ='14. 현금흐름계획'!$D$9 | G29: ='14. 현금흐름계획'!$D$9 | H29: ='14. 현금흐름계획'!$D$9
B30: Ⅲ. 이익잉여금 | C30: =0 | D30: ='12 손익계획'!C26 | E30: ='12 손익계획'!D26+D30 | F30: ='12 손익계획'!E26+E30 | G30: ='12 손익계획'!F26+F30 | H30: ='12 손익계획'!G26+G30
B31: 자본 총계 | C31: =SUM(C28,C30) | D31: =SUM(D28:D30) | E31: =SUM(E28:E30) | F31: =SUM(F28:F30) | G31: =SUM(G28:G30) | H31: =SUM(H28:H30)
B32: 부채와 자본 총계 | C32: =C31+C26 | D32: =D31+D26 | E32: =E31+E26 | F32: =F31+F26 | G32: =G31+G26 | H32: =H31+H26
D34: =D22-D32 | E34: =E22-E32 | F34: =F22-F32 | G34: =G22-G32 | H34: =H22-H32

Sheet 14. 현금흐름계획
B2: 14. 현금흐름계획
H4: (단위: 천원)
B5: 구 분 | D5: 연 도 별
I6: 비고
B7: 조 달 | C7: 농산물 판매대금 | D7: ='12 손익계획'!C6 | E7: ='12 손익계획'!D6 | F7: ='12 손익계획'!E6 | G7: ='12 손익계획'!F6 | H7: ='12 손익계획'!G6
C8: 부산물 매출 | D8: =0 | E8: =0 | F8: =0 | G8: =0 | H8: =0
C9: 보조금 | D9: ='3.투자계획'!G22 | E9: =0 | F9: =0 | G9: =0 | H9: =0
C10: 영농착수금 | D10: =SUM('1. 기초재무상태조사'!E39:F39) | E10: =0 | F10: =0 | G10: =0 | H10: =0
C11: 자산매각대금 | D11: =0 | E11: =0 | F11: =0 | G11: =0 | H11: =0
C12: 융자금 | D12: ='4. 원리금상환계획'!D38 | E12: ='3.투자계획'!F9 | F12: ='3.투자계획'!$F10 | G12: ='3.투자계획'!$F11 | H12: ='3.투자계획'!$F12
C13: 기타 수입 | D13: =0 | E13: =0 | F13: =0 | G13: =0 | H13: =0
C14: 소 계(A) | D14: =SUM(D7:D13) | E14: =SUM(E7:E13) | F14: =SUM(F7:F13) | G14: =SUM(G7:G13) | H14: =SUM(H7:H13)
B15: 지 출 | C15: 시설투자 | D15: =SUM('3.투자계획'!E20:E23) | F15: =0 | G15: =0 | H15: =0
C16: 농기계투자 | D16: =SUM('3.투자계획'!E19:E19) | F16: =0 | G16: =0 | H16: =0
C17: 당기총생산 원가 | D17: ='11. 생산원가계획'!C31-'11. 생산원가계획'!C21 | E17: ='11. 생산원가계획'!D31-'11. 생산원가계획'!D21 | F17: ='11. 생산원가계획'!E31-'11. 생산원가계획'!E21 | G17: ='11. 생산원가계획'!F31-'11. 생산원가계획'!F21 | H17: ='11. 생산원가계획'!G31-'11. 생산원가계획'!G21
C18: 판매 및 일반관리비 | D18: =0 | E18: ='12 손익계획'!D11 | F18: ='12 손익계획'!E11 | G18: ='12 손익계획'!F11 | H18: ='12 손익계획'!G11
C19: 영업외 비용 | D19: ='12 손익계획'!C20 | E19: ='12 손익계획'!D20 | F19: ='12 손익계획'!E20 | G19: ='12 손익계획'!F20 | H19: ='12 손익계획'!G20
C20: 융자원금상환 | D20: =0 | E20: =0 | F20: =0 | G20: ='4. 원리금상환계획'!D11 | H20: ='4. 원리금상환계획'!D12
C21: 소 계(B) | D21: =SUM(D15:D20) | E21: =SUM(E15:E20) | F21: =SUM(F15:F20) | G21: =SUM(G15:G20) | H21: =SUM(H15:H20)
B22: 수지균형(C) (C=A-B) | D22: =D14-D21 | E22: =E14-E21 | F22: =F14-F21 | G22: =G14-G21 | H22: =H14-H21
B23: 누적수지균형(D) (D=전년도D+금년도C) | D23: =D14-D21 | E23: =D23+E22 | F23: =E23+F22 | G23: =F23+G22 | H23: =G23+H22
B24: * 당기 총생산원가 중 감가상각비는 제외

Sheet 15.추정소득분석
B2: 15. 추정소득분석
I3: (단위:천원)
B4: 비목별
B5: 조수입 | C5: 주산물가액 | E5: =' 5. 판매계획'!C44 | F5: =' 5. 판매계획'!E44 | G5: =' 5. 판매계획'!G44 | H5: =' 5. 판매계획'!I44 | I5: =' 5. 판매계획'!K44
C6: 부산물가액 | E6: =0 | F6: =0 | G6: =0 | H6: =0 | I6: =0
C7: 계 | F7: =SUM(F5,F6) | G7: =SUM(G5,G6) | H7: =SUM(H5,H6) | I7: =SUM(I5,I6)
B8: 경 영 비 | C8: 중간재비 | D8: 종자비 | E8: ='11. 생산원가계획'!C6 | F8: ='11. 생산원가계획'!D6 | G8: ='11. 생산원가계획'!E6 | H8: ='11. 생산원가계획'!F6 | I8: ='11. 생산원가계획'!G6
D9: 무기질비료비 | E9: ='11. 생산원가계획'!C7 | F9: ='11. 생산원가계획'!D7 | G9: ='11. 생산원가계획'!E7 | H9: ='11. 생산원가계획'!F7 | I9: ='11. 생산원가계획'!G7
D10: 유기질비료비 | E10: ='11. 생산원가계획'!C8 | F10: ='11. 생산원가계획'!D8 | G10: ='11. 생산원가계획'!E8 | H10: ='11. 생산원가계획'!F8 | I10: ='11. 생산원가계획'!G8
D11: 작물보호제비 | E11: ='11. 생산원가계획'!C9 | F11: ='11. 생산원가계획'!D9 | G11: ='11. 생산원가계획'!E9 | H11: ='11. 생산원가계획'!F9 | I11: ='11. 생산원가계획'!G9
D12: 기타재료비 | E12: ='11. 생산원가계획'!C10 | F12: ='11. 생산원가계획'!D10 | G12: ='11. 생산원가계획'!E10 | H12: ='11. 생산원가계획'!F10 | I12: ='11. 생산원가계획'!G10
D13: 영농광열비 | E13: ='11. 생산원가계획'!C20 | F13: ='11. 생산원가계획'!D20 | G13: ='11. 생산원가계획'!E20 | H13: ='11. 생산원가계획'!F20 | I13: ='11. 생산원가계획'!G20
D14: 소농구비 | E14: ='11. 생산원가계획'!C29 | F14: ='11. 생산원가계획'!C29 | G14: ='11. 생산원가계획'!C29 | H14: ='11. 생산원가계획'!C29 | I14: ='11. 생산원가계획'!C29
D15: 대농구상각비 | E15: ='11. 생산원가계획'!C23 | F15: ='11. 생산원가계획'!D23 | G15: ='11. 생산원가계획'!E23 | H15: ='11. 생산원가계획'!F23 | I15: ='11. 생산원가계획'!G23
D16: 영농시설상각비 | E16: ='11. 생산원가계획'!C22 | F16: ='11. 생산원가계획'!D22 | G16: ='11. 생산원가계획'!E22 | H16: ='11. 생산원가계획'!F22 | I16: ='11. 생산원가계획'!G22
D17: 생물자산상각비 | E17: ='11. 생산원가계획'!C24 | F17: ='11. 생산원가계획'!D24 | G17: ='11. 생산원가계획'!E24 | H17: ='11. 생산원가계획'!F24 | I17: ='11. 생산원가계획'!G24
D18: 수선비 | E18: ='11. 생산원가계획'!C17 | F18: ='11. 생산원가계획'!D17 | G18: ='11. 생산원가계획'!E17 | H18: ='11. 생산원가계획'!F17 | I18: ='11. 생산원가계획'!G17
D19: 기타 요금 | E19: =0 | F19: =0 | G19: =0 | H19: =0 | I19: =0
D20: 계 | E20: =SUM(E8:E19) | F20: =SUM(F8:F19) | G20: =SUM(G8:G19) | H20: =SUM(H8:H19) | I20: =SUM(I8:I19)
C21: 임차료 | D21: 대농기구 | E21: ='11. 생산원가계획'!C26 | F21: ='11. 생산원가계획'!C26 | G21: ='11. 생산원가계획'!E26 | H21: ='11. 생산원가계획'!E26 | I21: ='11. 생산원가계획'!F26
D22: 토지 | E22: ='11. 생산원가계획'!C27 | F22: ='11. 생산원가계획'!D27 | G22: ='11. 생산원가계획'!E27 | H22: ='11. 생산원가계획'!E27 | I22: ='11. 생산원가계획'!F27
C23: 판매비 및 관리비 | E23: ='12 손익계획'!C11 | F23: ='12 손익계획'!D11 | G23: ='12 손익계획'!E11 | H23: ='12 손익계획'!F11 | I23: ='12 손익계획'!G11
C24: 위탁영농비 | E24: =0 | F24: =0 | G24: =0 | H24: =0 | I24: =0
C25: 고용노동비 | E25: ='11. 생산원가계획'!C15 | F25: ='11. 생산원가계획'!D15 | G25: ='11. 생산원가계획'!E15 | H25: ='11. 생산원가계획'!F15 | I25: ='11. 생산원가계획'!G15
C26: 계 | E26: =SUM(E20:E25) | F26: =SUM(F20:F25) | G26: =SUM(G20:G25) | H26: =SUM(H20:H25) | I26: =SUM(I20:I25)
B27: 영농잉여 | E27: =E7-E26 | F27: =F7-F26 | G27: =G7-G26 | H27: =H7-H26 | I27: =I7-I26
B28: 영농잉여율 | F28: =F27/F7*100 | G28: =G27/G7*100 | H28: =H27/H7*100 | I28: =I27/I7*100
B29: 이자비용 | E29: ='14. 현금흐름계획'!D19 | F29: ='14. 현금흐름계획'!E19 | G29: ='14. 현금흐름계획'!F19 | H29: ='14. 현금흐름계획'!G19 | I29: ='14. 현금흐름계획'!H19
B30: 자가노동비 | E30: ='11. 생산원가계획'!C12 | F30: ='11. 생산원가계획'!D12 | G30: ='11. 생산원가계획'!E12 | H30: ='11. 생산원가계획'!F12 | I30: ='11. 생산원가계획'!G12
B31: 소 득 | E31: =E27-E29-E30 | F31: =F27-F29-F30 | G31: =G27-G29-G30 | H31: =H27-H29-H30 | I31: =I27-I29-I30
B32: 소 득 율(%) | F32: =F31/F7 | G32: =G31/G7 | H32: =H31/H7 | I32: =I31/I7

Sheet 참고1. 모델농장분석
B2: 참고1. 모델농장 분석 요약
B5: 1) 농장명
B6: 2) 농장주
B7: 3) 농장주소
B8: 4) 농장연혁
B9: 5) 재배작목
B10: 6) 농장규모
B11: 7) 농장인원
B12: 8) 주요생산시설
B14: 9) 생산현황
B15: 10) 판매현황
B16: 11) 수확후 처리 및 가공방법
... B19: 14) 시사점
